Workbook

Sheet Weekdays
A1: Hour | B1: January | C1: February | D1: March | E1: April | F1: May | G1: June | H1: July | I1: August | J1: September | K1: October | L1: November | M1: December
A2: 0 | B2: 1.396 | C2: 1.396 | D2: 1.396 | E2: 1.396 | F2: 1.396 | G2: 1.396 | H2: 1.396 | I2: 1.396 | J2: 1.396 | K2: 1.396 | L2: 1.396 | M2: 1.396
A3: 1 | B3: 1.499 | C3: 1.499 | D3: 1.499 | E3: 1.499 | F3: 1.499 | G3: 1.499 | H3: 1.499 | I3: 1.499 | J3: 1.499 | K3: 1.499 | L3: 1.499 | M3: 1.499
A4: 2 | B4: 1.564 | C4: 1.564 | D4: 1.564 | E4: 1.564 | F4: 1.564 | G4: 1.564 | H4: 1.564 | I4: 1.564 | J4: 1.564 | K4: 1.564 | L4: 1.564 | M4: 1.564
A5: 3 | B5: 1.77 | C5: 1.77 | D5: 1.77 | E5: 1.77 | F5: 1.77 | G5: 1.77 | H5: 1.77 | I5: 1.77 | J5: 1.77 | K5: 1.77 | L5: 1.77 | M5: 1.77
A6: 4 | B6: 1.197 | C6: 1.197 | D6: 1.197 | E6: 1.197 | F6: 1.197 | G6: 1.197 | H6: 1.197 | I6: 1.197 | J6: 1.197 | K6: 1.197 | L6: 1.197 | M6: 1.197
A7: 5 | B7: 1.237 | C7: 1.237 | D7: 1.237 | E7: 1.237 | F7: 1.237 | G7: 1.237 | H7: 1.237 | I7: 1.237 | J7: 1.237 | K7: 1.237 | L7: 1.237 | M7: 1.237
A8: 6 | B8: 0.805 | C8: 0.805 | D8: 0.805 | E8: 0.805 | F8: 0.805 | G8: 0.805 | H8: 0.805 | I8: 0.805 | J8: 0.805 | K8: 0.805 | L8: 0.805 | M8: 0.805
A9: 7 | B9: 0.886 | C9: 0.886 | D9: 0.886 | E9: 0.886 | F9: 0.886 | G9: 0.886 | H9: 0.886 | I9: 0.886 | J9: 0.886 | K9: 0.886 | L9: 0.886 | M9: 0.886
A10: 8 | B10: 0.734 | C10: 0.734 | D10: 0.734 | E10: 0.734 | F10: 0.734 | G10: 0.734 | H10: 0.734 | I10: 0.734 | J10: 0.734 | K10: 0.734 | L10: 0.734 | M10: 0.734
A11: 9 | B11: 1.197 | C11: 1.197 | D11: 1.197 | E11: 1.197 | F11: 1.197 | G11: 1.197 | H11: 1.197 | I11: 1.197 | J11: 1.197 | K11: 1.197 | L11: 1.197 | M11: 1.197
A12: 10 | B12: 0.901 | C12: 0.901 | D12: 0.901 | E12: 0.901 | F12: 0.901 | G12: 0.901 | H12: 0.901 | I12: 0.901 | J12: 0.901 | K12: 0.901 | L12: 0.901 | M12: 0.901
A13: 11 | B13: 1.235 | C13: 1.235 | D13: 1.235 | E13: 1.235 | F13: 1.235 | G13: 1.235 | H13: 1.235 | I13: 1.235 | J13: 1.235 | K13: 1.235 | L13: 1.235 | M13: 1.235
... A25: 23 | B25: 1.533 | C25: 1.533 | D25: 1.533 | E25: 1.533 | F25: 1.533 | G25: 1.533 | H25: 1.533 | I25: 1.533 | J25: 1.533 | K25: 1.533 | L25: 1.533 | M25: 1.533

Sheet Weekends
A1: Hour | B1: January | C1: February | D1: March | E1: April | F1: May | G1: June | H1: July | I1: August | J1: September | K1: October | L1: November | M1: December
A2: 0 | B2: 1.358 | C2: 1.358 | D2: 1.358 | E2: 1.358 | F2: 1.358 | G2: 1.358 | H2: 1.358 | I2: 1.358 | J2: 1.358 | K2: 1.358 | L2: 1.358 | M2: 1.358
A3: 1 | B3: 1.634 | C3: 1.634 | D3: 1.634 | E3: 1.634 | F3: 1.634 | G3: 1.634 | H3: 1.634 | I3: 1.634 | J3: 1.634 | K3: 1.634 | L3: 1.634 | M3: 1.634
A4: 2 | B4: 1.554 | C4: 1.554 | D4: 1.554 | E4: 1.554 | F4: 1.554 | G4: 1.554 | H4: 1.554 | I4: 1.554 | J4: 1.554 | K4: 1.554 | L4: 1.554 | M4: 1.554
A5: 3 | B5: 1.61 | C5: 1.61 | D5: 1.61 | E5: 1.61 | F5: 1.61 | G5: 1.61 | H5: 1.61 | I5: 1.61 | J5: 1.61 | K5: 1.61 | L5: 1.61 | M5: 1.61
A6: 4 | B6: 1.291 | C6: 1.291 | D6: 1.291 | E6: 1.291 | F6: 1.291 | G6: 1.291 | H6: 1.291 | I6: 1.291 | J6: 1.291 | K6: 1.291 | L6: 1.291 | M6: 1.291
A7: 5 | B7: 0.951 | C7: 0.951 | D7: 0.951 | E7: 0.951 | F7: 0.951 | G7: 0.951 | H7: 0.951 | I7: 0.951 | J7: 0.951 | K7: 0.951 | L7: 0.951 | M7: 0.951
A8: 6 | B8: 0.731 | C8: 0.731 | D8: 0.731 | E8: 0.731 | F8: 0.731 | G8: 0.731 | H8: 0.731 | I8: 0.731 | J8: 0.731 | K8: 0.731 | L8: 0.731 | M8: 0.731
A9: 7 | B9: 0.805 | C9: 0.805 | D9: 0.805 | E9: 0.805 | F9: 0.805 | G9: 0.805 | H9: 0.805 | I9: 0.805 | J9: 0.805 | K9: 0.805 | L9: 0.805 | M9: 0.805
A10: 8 | B10: 0.858 | C10: 0.858 | D10: 0.858 | E10: 0.858 | F10: 0.858 | G10: 0.858 | H10: 0.858 | I10: 0.858 | J10: 0.858 | K10: 0.858 | L10: 0.858 | M10: 0.858
A11: 9 | B11: 1.106 | C11: 1.106 | D11: 1.106 | E11: 1.106 | F11: 1.106 | G11: 1.106 | H11: 1.106 | I11: 1.106 | J11: 1.106 | K11: 1.106 | L11: 1.106 | M11: 1.106
A12: 10 | B12: 0.959 | C12: 0.959 | D12: 0.959 | E12: 0.959 | F12: 0.959 | G12: 0.959 | H12: 0.959 | I12: 0.959 | J12: 0.959 | K12: 0.959 | L12: 0.959 | M12: 0.959
A13: 11 | B13: 1.145 | C13: 1.145 | D13: 1.145 | E13: 1.145 | F13: 1.145 | G13: 1.145 | H13: 1.145 | I13: 1.145 | J13: 1.145 | K13: 1.145 | L13: 1.145 | M13: 1.145
... A25: 23 | B25: 1.755 | C25: 1.755 | D25: 1.755 | E25: 1.755 | F25: 1.755 | G25: 1.755 | H25: 1.755 | I25: 1.755 | J25: 1.755 | K25: 1.755 | L25: 1.755 | M25: 1.755

Sheet Sheet1
A1: Date & Time | B1: National Grid (kWh) | C1: Generator (kWh) | D1: Total Load (kWh)
A2: =Sheet2!A2 -> 43101 | B2: 0.98 | C2: 0 | D2: =B2+C2 -> 0.98
A3: =Sheet2!A3 -> 43101.042 | B3: 0.88 | C3: 0 | D3: =B3+C3 -> 0.88
A4: =Sheet2!A4 -> 43101.083 | B4: 0.89 | C4: 0 | D4: =B4+C4 -> 0.89
A5: =Sheet2!A5 -> 43101.125 | B5: 0.81 | C5: 0 | D5: =B5+C5 -> 0.81
A6: =Sheet2!A6 -> 43101.167 | B6: 0.7 | C6: 0 | D6: =B6+C6 -> 0.7
A7: =Sheet2!A7 -> 43101.208 | B7: 0.94 | C7: 0 | D7: =B7+C7 -> 0.94
A8: =Sheet2!A8 -> 43101.25 | B8: 1.19 | C8: 0 | D8: =B8+C8 -> 1.19
A9: =Sheet2!A9 -> 43101.292 | B9: 1.29 | C9: 0 | D9: =B9+C9 -> 1.29
A10: =Sheet2!A10 -> 43101.333 | B10: 1.08 | C10: 0 | D10: =B10+C10 -> 1.08
A11: =Sheet2!A11 -> 43101.375 | B11: 1.46 | C11: 0 | D11: =B11+C11 -> 1.46
A12: =Sheet2!A12 -> 43101.417 | B12: 0 | C12: 0.57 | D12: =B12+C12 -> 0.57
A13: =Sheet2!A13 -> 43101.458 | B13: 0 | C13: 0.7 | D13: =B13+C13 -> 0.7
... A8761: =Sheet2!A8761 -> 0 | B8761: 1.06 | C8761: 0 | D8761: =B8761+C8761 -> 1.06
A8762: Annual Total | B8762: =SUM(B2:B8761) -> 14909.95 | C8762: =SUM(C2:C8761) -> 6997.12 | D8762: =SUM(D2:D8761) -> 21907.07
A8763: Hourly Average | B8763: =AVERAGE(B2:B8761) -> 1.7020491 | C8763: =AVERAGE(C2:C8761) -> 0.79875799 | D8763: =AVERAGE(D2:D8761) -> 2.5008071
A8764: Peak Load | B8764: =MAX(B2:B8761) -> 22.44 | C8764: =MAX(C2:C8761) -> 4.85 | D8764: =MAX(D2:D8761) -> 22.44

Sheet Sheet2
A1: Timestamp | B1: Power (kWh) (BG1F3) | C1: Power (kWh) (BG1DG)
A2: 43101 | B2: 0.98 | C2: 0
A3: 43101.042 | B3: 0.88 | C3: 0
A4: 43101.083 | B4: 0.89 | C4: 0
A5: 43101.125 | B5: 0.81 | C5: 0
A6: 43101.167 | B6: 0.7 | C6: 0
A7: 43101.208 | B7: 0.94 | C7: 0
A8: 43101.25 | B8: 1.19 | C8: 0
A9: 43101.292 | B9: 1.29 | C9: 0
A10: 43101.333 | B10: 1.08 | C10: 0
A11: 43101.375 | B11: 1.46 | C11: 0
A12: 43101.417 | B12: 0 | C12: =0.57+0.31 -> 0.88
A13: 43101.458 | B13: 0 | C13: 0.7
A14: 43101.5 | B14: 0 | C14: =0.44+D14 -> 0.44
A15: 43101.542 | B15: 0.95 | C15: 0
A16: 43101.583 | B16: 1.32 | C16: 0
A17: 43101.625 | B17: 1.41 | C17: 0
A18: 43101.667 | B18: 0 | C18: =0.61+D18 -> 0.61
A19: 43101.708 | B19: 0 | C19: 0.96
A20: 43101.75 | B20: 0 | C20: =0.2+D20 -> 0.2
A21: 43101.792 | B21: 0.82 | C21: 0
A22: 43101.833 | B22: 1.1 | C22: 0
A23: 43101.875 | B23: 0.96 | C23: 0
A24: 43101.917 | B24: 0.95 | C24: 0
A25: 43101.958 | B25: 0.43 | C25: 0
A26: 43102 | B26: 0.55 | C26: 0
A27: 43102.042 | B27: 0.38 | C27: 0
A28: 43102.083 | B28: 0.6 | C28: 0
A29: 43102.125 | B29: 0.97 | C29: 0
A30: 43102.167 | B30: 0.82 | C30: 0
A31: 43102.208 | B31: 0.62 | C31: 0
A32: 43102.25 | B32: 0 | C32: =0.21+D32 -> 0.21
A33: 43102.292 | B33: 0 | C33: 0.42
A34: 43102.333 | B34: 0 | C34: =0.06+D34 -> 0.06
A35: 43102.375 | B35: 0.58 | C35: 0
A36: 43102.417 | B36: 0.58 | C36: 0
A37: 43102.458 | B37: 0.59 | C37: 0
A38: 43102.5 | B38: 0 | C38: =0.44+D38 -> 0.44
A39: 43102.542 | B39: 0 | C39: 1.08
A40: 43102.583 | B40: 0 | C40: =0.71+D40 -> 0.71
...

Sheet National Status
A1: Date & Time | B1: National Grid (kWh) | C1: Status (1=National / 0=No)
A2: =Sheet1!A2 -> 43101 | B2: =Sheet1!B2 -> 0.98 | C2: =IF(Sheet1!B2>0,1,0) -> 1
A3: =Sheet1!A3 -> 43101.042 | B3: =Sheet1!B3 -> 0.88 | C3: =IF(Sheet1!B3>0,1,0) -> 1
A4: =Sheet1!A4 -> 43101.083 | B4: =Sheet1!B4 -> 0.89 | C4: =IF(Sheet1!B4>0,1,0) -> 1
A5: =Sheet1!A5 -> 43101.125 | B5: =Sheet1!B5 -> 0.81 | C5: =IF(Sheet1!B5>0,1,0) -> 1
A6: =Sheet1!A6 -> 43101.167 | B6: =Sheet1!B6 -> 0.7 | C6: =IF(Sheet1!B6>0,1,0) -> 1
A7: =Sheet1!A7 -> 43101.208 | B7: =Sheet1!B7 -> 0.94 | C7: =IF(Sheet1!B7>0,1,0) -> 1
A8: =Sheet1!A8 -> 43101.25 | B8: =Sheet1!B8 -> 1.19 | C8: =IF(Sheet1!B8>0,1,0) -> 1
A9: =Sheet1!A9 -> 43101.292 | B9: =Sheet1!B9 -> 1.29 | C9: =IF(Sheet1!B9>0,1,0) -> 1
A10: =Sheet1!A10 -> 43101.333 | B10: =Sheet1!B10 -> 1.08 | C10: =IF(Sheet1!B10>0,1,0) -> 1
A11: =Sheet1!A11 -> 43101.375 | B11: =Sheet1!B11 -> 1.46 | C11: =IF(Sheet1!B11>0,1,0) -> 1
A12: =Sheet1!A12 -> 43101.417 | B12: =Sheet1!B12 -> 0 | C12: =IF(Sheet1!B12>0,1,0) -> 0
A13: =Sheet1!A13 -> 43101.458 | B13: =Sheet1!B13 -> 0 | C13: =IF(Sheet1!B13>0,1,0) -> 0
... A8761: =Sheet1!A8761 -> 0 | B8761: =Sheet1!B8761 -> 1.06 | C8761: =IF(Sheet1!B8761>0,1,0) -> 1
